Traceback (most recent call last):
  File "/Users/fsultan/opt/anaconda3/lib/python3.9/site-packages/jupyter_cache/executors/utils.py", line 58, in single_nb_execution
    executenb(
  File "/Users/fsultan/opt/anaconda3/lib/python3.9/site-packages/nbclient/client.py", line 1204, in execute
    return NotebookClient(nb=nb, resources=resources, km=km, **kwargs).execute()
  File "/Users/fsultan/opt/anaconda3/lib/python3.9/site-packages/nbclient/util.py", line 84, in wrapped
    return just_run(coro(*args, **kwargs))
  File "/Users/fsultan/opt/anaconda3/lib/python3.9/site-packages/nbclient/util.py", line 62, in just_run
    return loop.run_until_complete(coro)
  File "/Users/fsultan/opt/anaconda3/lib/python3.9/asyncio/base_events.py", line 647, in run_until_complete
    return future.result()
  File "/Users/fsultan/opt/anaconda3/lib/python3.9/site-packages/nbclient/client.py", line 663, in async_execute
    await self.async_execute_cell(
  File "/Users/fsultan/opt/anaconda3/lib/python3.9/site-packages/nbclient/client.py", line 965, in async_execute_cell
    await self._check_raise_for_error(cell, cell_index, exec_reply)
  File "/Users/fsultan/opt/anaconda3/lib/python3.9/site-packages/nbclient/client.py", line 862, in _check_raise_for_error
    raise CellExecutionError.from_cell_and_msg(cell, exec_reply_content)
nbclient.exceptions.CellExecutionError: An error occurred while executing the following cell:
------------------
import urllib.request
import os.path
import pandas as pd 

# Download data from the web directly
data_url = "https://www.ssa.gov/oact/babynames/names.zip"
local_filename = "../data/babynames.zip"
if not os.path.exists(local_filename): # if the data exists don't download again
    with urllib.request.urlopen(data_url) as resp, open(local_filename, 'wb') as f:
        f.write(resp.read())

        
# Load data without unzipping the file
import zipfile
babynames = [] 
with zipfile.ZipFile(local_filename, "r") as zf:
    data_files = [f for f in zf.filelist if f.filename[-3:] == "txt"]
    def extract_year_from_filename(fn):
        return int(fn[3:7])
    for f in data_files:
        year = extract_year_from_filename(f.filename)
        with zf.open(f) as fp:
            df = pd.read_csv(fp, names=["Name", "Sex", "Count"])
            df["Year"] = year
            babynames.append(df)
babynames = pd.concat(babynames)

babynames
------------------

[0;31m---------------------------------------------------------------------------[0m
[0;31mFileNotFoundError[0m                         Traceback (most recent call last)
Input [0;32mIn [1][0m, in [0;36m<cell line: 8>[0;34m()[0m
[1;32m      7[0m local_filename [38;5;241m=[39m [38;5;124m"[39m[38;5;124m../data/babynames.zip[39m[38;5;124m"[39m
[1;32m      8[0m [38;5;28;01mif[39;00m [38;5;129;01mnot[39;00m os[38;5;241m.[39mpath[38;5;241m.[39mexists(local_filename): [38;5;66;03m# if the data exists don't download again[39;00m
[0;32m----> 9[0m     [38;5;28;01mwith[39;00m urllib[38;5;241m.[39mrequest[38;5;241m.[39murlopen(data_url) [38;5;28;01mas[39;00m resp, [38;5;28;43mopen[39;49m[43m([49m[43mlocal_filename[49m[43m,[49m[43m [49m[38;5;124;43m'[39;49m[38;5;124;43mwb[39;49m[38;5;124;43m'[39;49m[43m)[49m [38;5;28;01mas[39;00m f:
[1;32m     10[0m         f[38;5;241m.[39mwrite(resp[38;5;241m.[39mread())
[1;32m     13[0m [38;5;66;03m# Load data without unzipping the file[39;00m

[0;31mFileNotFoundError[0m: [Errno 2] No such file or directory: '../data/babynames.zip'
FileNotFoundError: [Errno 2] No such file or directory: '../data/babynames.zip'

